Workbook

Sheet Summary
A1: Target Corporation - Three-Statement Model Summary
A2: USD millions, except percentages
B4: ='Three Statements'!B4 -> FY2023 | C4: ='Three Statements'!C4 -> FY2024 | D4: ='Three Statements'!D4 -> FY2025 | E4: ='Three Statements'!E4 -> FY2026F | F4: ='Three Statements'!F4 -> FY2027F | G4: ='Three Statements'!G4 -> FY2028F
A6: Net sales | B6: ='Three Statements'!B7 -> 107412 | C6: ='Three Statements'!C7 -> 106566 | D6: ='Three Statements'!D7 -> 104780 | E6: ='Three Statements'!E7 -> 110019 | F6: ='Three Statements'!F7 -> 113319.57 | G6: ='Three Statements'!G7 -> 116719.16
A7: Operating income | B7: ='Three Statements'!B11 -> 5707 | C7: ='Three Statements'!C11 -> 5566 | D7: ='Three Statements'!D11 -> 5117 | E7: ='Three Statements'!E11 -> 6601.14 | F7: ='Three Statements'!F11 -> 6005.9372 | G7: ='Three Statements'!G11 -> 6536.2728
A8: Operating margin | B8: =B7/B6 -> 0.053131866 | C8: =C7/C6 -> 0.052230543 | D8: =D7/D6 -> 0.048835656 | E8: =E7/E6 -> 0.06 | F8: =F7/F6 -> 0.053 | G8: =G7/G6 -> 0.056
A9: Net earnings | B9: ='Three Statements'!B16 -> 4138 | C9: ='Three Statements'!C16 -> 4091 | D9: ='Three Statements'!D16 -> 3705 | E9: ='Three Statements'!E16 -> 4817.1693 | F9: ='Three Statements'!F16 -> 4348.6974 | G9: ='Three Statements'!G16 -> 4746.5851
A10: Operating cash flow | B10: ='Three Statements'!B61 -> 8621 | C10: ='Three Statements'!C61 -> 7367 | D10: ='Three Statements'!D61 -> 6562 | E10: ='Three Statements'!E61 -> 8612.1525 | F10: ='Three Statements'!F61 -> 8166.6474 | G10: ='Three Statements'!G61 -> 8666.32
A11: Capital spending | B11: ='Three Statements'!B64 -> -4806 | C11: ='Three Statements'!C64 -> -2891 | D11: ='Three Statements'!D64 -> -3727 | E11: ='Three Statements'!E64 -> -3913.35 | F11: ='Three Statements'!F64 -> -4030.7505 | G11: ='Three Statements'!G64 -> -4151.673
A12: Free cash flow | B12: =B10+B11 -> 3815 | C12: =C10+C11 -> 4476 | D12: =D10+D11 -> 2835 | E12: =E10+E11 -> 4698.8025 | F12: =F10+F11 -> 4135.8969 | G12: =G10+G11 -> 4514.647
A13: Ending cash | B13: ='Three Statements'!B78 -> 3805 | C13: ='Three Statements'!C78 -> 4762 | D13: ='Three Statements'!D78 -> 5488 | E13: ='Three Statements'!E78 -> 8133.8025 | F13: ='Three Statements'!F78 -> 10216.699 | G13: ='Three Statements'!G78 -> 12678.346
A14: Balance sheet difference | B14: =Checks!B6 -> 0 | C14: =Checks!C6 -> 0 | D14: =Checks!D6 -> 0 | E14: =Checks!E6 -> 0 | F14: =Checks!F6 -> 0 | G14: =Checks!G6 -> 0
A16: Key findings: FY2026 forecast vs. FY2025 actual
A17: Net sales growth | B17: =E6/D6-1 -> 0.05
A18: Operating margin change (percentage points) | B18: =(E8-D8)*100 -> 1.1164344
A19: Free cash flow increase (USD millions) | B19: =E12-D12 -> 1863.8025
A21: Fiscal year | B21: =B4 -> FY2023 | C21: =C4 -> FY2024 | D21: =D4 -> FY2025 | E21: =E4 -> FY2026F | F21: =F4 -> FY2027F | G21: =G4 -> FY2028F
A22: Free cash flow | B22: =B12 -> 3815 | C22: =C12 -> 4476 | D22: =D12 -> 2835 | E22: =E12 -> 4698.8025 | F22: =F12 -> 4135.8969 | G22: =G12 -> 4514.647
A26: FY2023–FY2025: historical financial statements
A27: FY2026–FY2028: assumption-based forecasts
A28: Sales, margins, working capital, and capital spending drive the forecast
A29: Cash flows into the balance sheet; all balance sheet checks equal zero
A31: Forecast assumptions: 5%/3%/3% sales growth; 23% tax rate
A32: Working capital and capital spending use FY2025 ratios
A33: Debt and lease balances are held constant; dividends use FY2025 cash amount
A34: Interest is modeled as 0.4% of sales, rather than from a debt schedule
A37: Sources and forecast context
A38: Historical data: Target 2025 Annual Report / Form 10-K
A39: FY2026 context: Target Q2 2026 earnings release, August 19, 2026
A40: FY2026 operating margin includes an expected tariff-refund benefit; FY2027–FY2028 are analyst assumptions
... A43: https://corporate.target.com/press/release/2026/08/target-corporation-reports-second-quarter-earnings

Sheet Assumptions
A1: Target Corporation - Forecast Assumptions
A2: Forecast prepared using information available through September 2026
A4: Fiscal year | E4: FY2026F | F4: FY2027F | G4: FY2028F
A6: Net sales growth | E6: 0.05 | F6: 0.03 | G6: 0.03
A7: Gross margin | E7: 0.292 | F7: 0.285 | G7: 0.287
A8: SG&A / sales | E8: 0.207 | F8: 0.207 | G8: 0.206
A9: Income statement depreciation / sales | E9: 0.025 | F9: 0.025 | G9: 0.025
A10: Net interest expense / sales | E10: 0.004 | F10: 0.004 | G10: 0.004
A11: Net other income (USD millions) | E11: 95 | F11: 95 | G11: 95
A12: Effective tax rate | E12: 0.23 | F12: 0.23 | G12: 0.23

Sheet Three Statements
A1: Target Corporation - Three-Statement Model
A2: USD millions
A4: Fiscal year | B4: =Historical!B4 -> FY2023 | C4: =Historical!C4 -> FY2024 | D4: =Historical!D4 -> FY2025 | E4: =Assumptions!E4 -> FY2026F | F4: =Assumptions!F4 -> FY2027F | G4: =Assumptions!G4 -> FY2028F
A6: INCOME STATEMENT
A7: Net sales | B7: =Historical!B7 -> 107412 | C7: =Historical!C7 -> 106566 | D7: =Historical!D7 -> 104780 | E7: =Schedules!E6 -> 110019 | F7: =Schedules!F6 -> 113319.57 | G7: =Schedules!G6 -> 116719.16
A8: Cost of sales | B8: =Historical!B8 -> 77828 | C8: =Historical!C8 -> 76502 | D8: =Historical!D8 -> 75511 | E8: =E7*(1-Schedules!E8) -> 77893.452 | F8: =F7*(1-Schedules!F8) -> 81023.493 | G8: =G7*(1-Schedules!G8) -> 83220.759
A9: Selling, general and administrative expenses | B9: =Historical!B9 -> 21462 | C9: =Historical!C9 -> 21969 | D9: =Historical!D9 -> 21535 | E9: =E7*Schedules!E9 -> 22773.933 | F9: =F7*Schedules!F9 -> 23457.151 | G9: =G7*Schedules!G9 -> 24044.146
A10: Depreciation and amortization — income statement | B10: =Historical!B10 -> 2415 | C10: =Historical!C10 -> 2529 | D10: =Historical!D10 -> 2617 | E10: =E7*Schedules!E12 -> 2750.475 | F10: =F7*Schedules!F12 -> 2832.9893 | G10: =G7*Schedules!G12 -> 2917.9789
A11: Operating income | B11: =B7-B8-B9-B10 -> 5707 | C11: =C7-C8-C9-C10 -> 5566 | D11: =D7-D8-D9-D10 -> 5117 | E11: =E7-E8-E9-E10 -> 6601.14 | F11: =F7-F8-F9-F10 -> 6005.9372 | G11: =G7-G8-G9-G10 -> 6536.2728
A12: Net interest expense | B12: =Historical!B12 -> 502 | C12: =Historical!C12 -> 411 | D12: =Historical!D12 -> 445 | E12: =E7*Assumptions!E10 -> 440.076 | F12: =F7*Assumptions!F10 -> 453.27828 | G12: =G7*Assumptions!G10 -> 466.87663
A13: Net other income | B13: =Historical!B13 -> 92 | C13: =Historical!C13 -> 106 | D13: =Historical!D13 -> 95 | E13: =Assumptions!E11 -> 95 | F13: =Assumptions!F11 -> 95 | G13: =Assumptions!G11 -> 95
A14: Earnings before income taxes | B14: =B11-B12+B13 -> 5297 | C14: =C11-C12+C13 -> 5261 | D14: =D11-D12+D13 -> 4767 | E14: =E11-E12+E13 -> 6256.064 | F14: =F11-F12+F13 -> 5647.6589 | G14: =G11-G12+G13 -> 6164.3962
A15: Provision for income taxes | B15: =Historical!B15 -> 1159 | C15: =Historical!C15 -> 1170 | D15: =Historical!D15 -> 1062 | E15: =E14*Schedules!E11 -> 1438.8947 | F15: =F14*Schedules!F11 -> 1298.9616 | G15: =G14*Schedules!G11 -> 1417.8111
A16: Net earnings | B16: =B14-B15 -> 4138 | C16: =C14-C15 -> 4091 | D16: =D14-D15 -> 3705 | E16: =E14-E15 -> 4817.1693 | F16: =F14-F15 -> 4348.6974 | G16: =G14-G15 -> 4746.5851
A19: BALANCE SHEET
A20: ASSETS
A21: Cash and cash equivalents | B21: =Historical!B21 -> 3805 | C21: =Historical!C21 -> 4762 | D21: =Historical!D21 -> 5488 | E21: =E78 -> 8133.8025 | F21: =F78 -> 10216.699 | G21: =G78 -> 12678.346
A22: Inventory | B22: =Historical!B22 -> 11886 | C22: =Historical!C22 -> 12740 | D22: =Historical!D22 -> 12304 | E22: =E8*Schedules!E14 -> 12692.204 | F22: =F8*Schedules!F14 -> 13202.223 | G22: =G8*Schedules!G14 -> 13560.252
A23: Other current assets | B23: =Historical!B23 -> 1807 | C23: =Historical!C23 -> 1952 | D23: =Historical!D23 -> 2213 | E23: =E7*Schedules!E16 -> 2323.65 | F23: =F7*Schedules!F16 -> 2393.3595 | G23: =G7*Schedules!G16 -> 2465.1603
A24: Total current assets | B24: =SUM(B21:B23) -> 17498 | C24: =SUM(C21:C23) -> 19454 | D24: =SUM(D21:D23) -> 20005 | E24: =SUM(E21:E23) -> 23149.657 | F24: =SUM(F21:F23) -> 25812.282 | G24: =SUM(G21:G23) -> 28703.759
A25: Property and equipment, net | B25: =Historical!B25 -> 33096 | C25: =Historical!C25 -> 33022 | D25: =Historical!D25 -> 33749 | E25: =D25-E64-E53 -> 34371.65 | F25: =E25-F64-F53 -> 35012.98 | G25: =F25-G64-G53 -> 35673.549
A26: Operating lease assets | B26: =Historical!B26 -> 3362 | C26: =Historical!C26 -> 3763 | D26: =Historical!D26 -> 3703 | E26: =D26 -> 3703 | F26: =E26 -> 3703 | G26: =F26 -> 3703
A27: Other noncurrent assets | B27: =Historical!B27 -> 1400 | C27: =Historical!C27 -> 1530 | D27: =Historical!D27 -> 2033 | E27: =D27 -> 2033 | F27: =E27 -> 2033 | G27: =F27 -> 2033
A28: Total assets | B28: =SUM(B24:B27) -> 55356 | C28: =SUM(C24:C27) -> 57769 | D28: =SUM(D24:D27) -> 59490 | E28: =SUM(E24:E27) -> 63257.307 | F28: =SUM(F24:F27) -> 66561.261 | G28: =SUM(G24:G27) -> 70113.308
A30: LIABILITIES
A31: Accounts payable | B31: =Historical!B31 -> 12098 | C31: =Historical!C31 -> 13053 | D31: =Historical!D31 -> 12622 | E31: =E8*Schedules!E15 -> 13020.237 | F31: =F8*Schedules!F15 -> 13543.438 | G31: =G8*Schedules!G15 -> 13910.721
A32: Accrued and other current liabilities | B32: =Historical!B32 -> 6090 | C32: =Historical!C32 -> 6110 | D32: =Historical!D32 -> 6478 | E32: =E7*Schedules!E17 -> 6801.9 | F32: =F7*Schedules!F17 -> 7005.957 | G32: =G7*Schedules!G17 -> 7216.1357
A33: Current portion of long-term debt and other borrowings | B33: =Historical!B33 -> 1116 | C33: =Historical!C33 -> 1636 | D33: =Historical!D33 -> 2130 | E33: =D33 -> 2130 | F33: =E33 -> 2130 | G33: =F33 -> 2130
A34: Total current liabilities | B34: =SUM(B31:B33) -> 19304 | C34: =SUM(C31:C33) -> 20799 | D34: =SUM(D31:D33) -> 21230 | E34: =SUM(E31:E33) -> 21952.137 | F34: =SUM(F31:F33) -> 22679.395 | G34: =SUM(G31:G33) -> 23256.856
A35: Long-term debt and other borrowings | B35: =Historical!B35 -> 14922 | C35: =Historical!C35 -> 14304 | D35: =Historical!D35 -> 14326 | E35: =D35 -> 14326 | F35: =E35 -> 14326 | G35: =F35 -> 14326
A36: Noncurrent operating lease liabilities | B36: =Historical!B36 -> 3279 | C36: =Historical!C36 -> 3582 | D36: =Historical!D36 -> 3462 | E36: =D36 -> 3462 | F36: =E36 -> 3462 | G36: =F36 -> 3462
A37: Deferred income taxes | B37: =Historical!B37 -> 2480 | C37: =Historical!C37 -> 2303 | D37: =Historical!D37 -> 2265 | E37: =D37 -> 2265 | F37: =E37 -> 2265 | G37: =F37 -> 2265
A38: Other noncurrent liabilities | B38: =Historical!B38 -> 1939 | C38: =Historical!C38 -> 2115 | D38: =Historical!D38 -> 2042 | E38: =D38 -> 2042 | F38: =E38 -> 2042 | G38: =F38 -> 2042
A39: Total noncurrent liabilities | B39: =SUM(B35:B38) -> 22620 | C39: =SUM(C35:C38) -> 22304 | D39: =SUM(D35:D38) -> 22095 | E39: =SUM(E35:E38) -> 22095 | F39: =SUM(F35:F38) -> 22095 | G39: =SUM(G35:G38) -> 22095
A41: SHAREHOLDERS' EQUITY
A42: Common stock | B42: =Historical!B42 -> 38 | C42: =Historical!C42 -> 38 | D42: =Historical!D42 -> 38 | E42: =D42 -> 38 | F42: =E42 -> 38 | G42: =F42 -> 38
A43: Additional paid-in capital | B43: =Historical!B43 -> 6761 | C43: =Historical!C43 -> 6996 | D43: =Historical!D43 -> 7247 | E43: =D43+E54 -> 7528 | F43: =E43+F54 -> 7809 | G43: =F43+G54 -> 8090
A44: Retained earnings | B44: =Historical!B44 -> 7093 | C44: =Historical!C44 -> 8090 | D44: =Historical!D44 -> 9297 | E44: =D44+E16+E71 -> 12061.169 | F44: =E44+F16+F71 -> 14356.867 | G44: =F44+G16+G71 -> 17050.452
A45: Accumulated other comprehensive loss | B45: =Historical!B45 -> -460 | C45: =Historical!C45 -> -458 | D45: =Historical!D45 -> -417 | E45: =D45 -> -417 | F45: =E45 -> -417 | G45: =F45 -> -417
A46: Total shareholders' equity | B46: =SUM(B42:B45) -> 13432 | C46: =SUM(C42:C45) -> 14666 | D46: =SUM(D42:D45) -> 16165 | E46: =SUM(E42:E45) -> 19210.169 | F46: =SUM(F42:F45) -> 21786.867 | G46: =SUM(G42:G45) -> 24761.452
...

Sheet Schedules
A1: Target Corporation — Historical Drivers
A2: Historical ratios used to inform forecast assumptions
A4: Fiscal year | B4: ='Three Statements'!B4 -> FY2023 | C4: ='Three Statements'!C4 -> FY2024 | D4: ='Three Statements'!D4 -> FY2025 | E4: =Assumptions!E4 -> FY2026F | F4: =Assumptions!F4 -> FY2027F | G4: =Assumptions!G4 -> FY2028F
A6: Net sales | B6: ='Three Statements'!B7 -> 107412 | C6: ='Three Statements'!C7 -> 106566 | D6: ='Three Statements'!D7 -> 104780 | E6: =D6*(1+E7) -> 110019 | F6: =E6*(1+F7) -> 113319.57 | G6: =F6*(1+G7) -> 116719.16
A7: Sales growth | C7: =C6/B6-1 -> -0.0078762149 | D7: =D6/C6-1 -> -0.016759567 | E7: =Assumptions!E6 -> 0.05 | F7: =Assumptions!F6 -> 0.03 | G7: =Assumptions!G6 -> 0.03
A8: Gross margin | B8: =('Three Statements'!B7-'Three Statements'!B8)/'Three Statements'!B7 -> 0.27542546 | C8: =('Three Statements'!C7-'Three Statements'!C8)/'Three Statements'!C7 -> 0.28211625 | D8: =('Three Statements'!D7-'Three Statements'!D8)/'Three Statements'!D7 -> 0.27933766 | E8: =Assumptions!E7 -> 0.292 | F8: =Assumptions!F7 -> 0.285 | G8: =Assumptions!G7 -> 0.287
A9: SG&A as % of sales | B9: ='Three Statements'!B9/'Three Statements'!B7 -> 0.19981008 | C9: ='Three Statements'!C9/'Three Statements'!C7 -> 0.20615393 | D9: ='Three Statements'!D9/'Three Statements'!D7 -> 0.20552586 | E9: =Assumptions!E8 -> 0.207 | F9: =Assumptions!F8 -> 0.207 | G9: =Assumptions!G8 -> 0.206
A10: Operating margin | B10: ='Three Statements'!B11/'Three Statements'!B7 -> 0.053131866 | C10: ='Three Statements'!C11/'Three Statements'!C7 -> 0.052230543 | D10: ='Three Statements'!D11/'Three Statements'!D7 -> 0.048835656 | E10: =E8-E9-E12 -> 0.06 | F10: =F8-F9-F12 -> 0.053 | G10: =G8-G9-G12 -> 0.056
A11: Effective tax rate | B11: ='Three Statements'!B15/'Three Statements'!B14 -> 0.2188031 | C11: ='Three Statements'!C15/'Three Statements'!C14 -> 0.22239118 | D11: ='Three Statements'!D15/'Three Statements'!D14 -> 0.22278162 | E11: =Assumptions!E12 -> 0.23 | F11: =Assumptions!F12 -> 0.23 | G11: =Assumptions!G12 -> 0.23
A12: Income statement depreciation / sales | B12: ='Three Statements'!B10/'Three Statements'!B7 -> 0.022483521 | C12: ='Three Statements'!C10/'Three Statements'!C7 -> 0.023731772 | D12: ='Three Statements'!D10/'Three Statements'!D7 -> 0.02497614 | E12: =Assumptions!E9 -> 0.025 | F12: =Assumptions!F9 -> 0.025 | G12: =Assumptions!G9 -> 0.025
A14: Inventory / cost of sales | B14: ='Three Statements'!B22/'Three Statements'!B8 -> 0.15272139 | C14: ='Three Statements'!C22/'Three Statements'!C8 -> 0.16653159 | D14: ='Three Statements'!D22/'Three Statements'!D8 -> 0.16294315 | E14: =$D14 -> 0.16294315 | F14: =$D14 -> 0.16294315 | G14: =$D14 -> 0.16294315
A15: Accounts payable / cost of sales | B15: ='Three Statements'!B31/'Three Statements'!B8 -> 0.15544534 | C15: ='Three Statements'!C31/'Three Statements'!C8 -> 0.17062299 | D15: ='Three Statements'!D31/'Three Statements'!D8 -> 0.16715445 | E15: =$D15 -> 0.16715445 | F15: =$D15 -> 0.16715445 | G15: =$D15 -> 0.16715445
A16: Other current assets / sales | B16: ='Three Statements'!B23/'Three Statements'!B7 -> 0.016823074 | C16: ='Three Statements'!C23/'Three Statements'!C7 -> 0.018317287 | D16: ='Three Statements'!D23/'Three Statements'!D7 -> 0.021120443 | E16: =$D16 -> 0.021120443 | F16: =$D16 -> 0.021120443 | G16: =$D16 -> 0.021120443
A17: Accrued current liabilities / sales | B17: ='Three Statements'!B32/'Three Statements'!B7 -> 0.056697576 | C17: ='Three Statements'!C32/'Three Statements'!C7 -> 0.05733536 | D17: ='Three Statements'!D32/'Three Statements'!D7 -> 0.061824776 | E17: =$D17 -> 0.061824776 | F17: =$D17 -> 0.061824776 | G17: =$D17 -> 0.061824776
A18: Cash flow depreciation / sales | B18: ='Three Statements'!B53/'Three Statements'!B7 -> 0.026077161 | C18: ='Three Statements'!C53/'Three Statements'!C7 -> 0.027973275 | D18: ='Three Statements'!D53/'Three Statements'!D7 -> 0.029910288 | E18: =$D18 -> 0.029910288 | F18: =$D18 -> 0.029910288 | G18: =$D18 -> 0.029910288
A19: Capital spending / sales | B19: =-'Three Statements'!B64/'Three Statements'!B7 -> 0.044743604 | C19: =-'Three Statements'!C64/'Three Statements'!C7 -> 0.027128728 | D19: =-'Three Statements'!D64/'Three Statements'!D7 -> 0.035569765 | E19: =$D19 -> 0.035569765 | F19: =$D19 -> 0.035569765 | G19: =$D19 -> 0.035569765

Sheet Historical
A1: Target Corporation — Historical Financial Data
A2: USD millions, except per-share data
A4: Fiscal year | B4: FY2023 | C4: FY2024 | D4: FY2025
A6: INCOME STATEMENT
A7: Net sales | B7: 107412 | C7: 106566 | D7: 104780
A8: Cost of sales | B8: 77828 | C8: 76502 | D8: 75511
A9: Selling, general and administrative expenses | B9: 21462 | C9: 21969 | D9: 21535
A10: Depreciation and amortization - income statement | B10: 2415 | C10: 2529 | D10: 2617
A11: Operating income | B11: 5707 | C11: 5566 | D11: 5117
A12: Net interest expense | B12: 502 | C12: 411 | D12: 445
A13: Net other income | B13: 92 | C13: 106 | D13: 95
A14: Earnings before income taxes | B14: 5297 | C14: 5261 | D14: 4767
A15: Provision for income taxes | B15: 1159 | C15: 1170 | D15: 1062
A16: Net earnings | B16: 4138 | C16: 4091 | D16: 3705
A19: BALANCE SHEET
A20: ASSETS
A21: Cash and cash equivalents | B21: 3805 | C21: 4762 | D21: 5488
A22: Inventory | B22: 11886 | C22: 12740 | D22: 12304
A23: Other current assets | B23: 1807 | C23: 1952 | D23: 2213
A24: Total current assets | B24: 17498 | C24: 19454 | D24: 20005
A25: Property and equipment, net | B25: 33096 | C25: 33022 | D25: 33749
A26: Operating lease assets | B26: 3362 | C26: 3763 | D26: 3703
A27: Other noncurrent assets | B27: 1400 | C27: 1530 | D27: 2033
A28: Total assets | B28: 55356 | C28: 57769 | D28: 59490
A30: LIABILITIES
A31: Accounts payable | B31: 12098 | C31: 13053 | D31: 12622
A32: Accrued and other current liabilities | B32: 6090 | C32: 6110 | D32: 6478
A33: Current portion of long-term debt and other borrowings | B33: 1116 | C33: 1636 | D33: 2130
A34: Total current liabilities | B34: 19304 | C34: 20799 | D34: 21230
A35: Long-term debt and other borrowings | B35: 14922 | C35: 14304 | D35: 14326
A36: Noncurrent operating lease liabilities | B36: 3279 | C36: 3582 | D36: 3462
A37: Deferred income taxes | B37: 2480 | C37: 2303 | D37: 2265
A38: Other noncurrent liabilities | B38: 1939 | C38: 2115 | D38: 2042
A39: Total noncurrent liabilities | B39: 22620 | C39: 22304 | D39: 22095
A41: SHAREHOLDERS' EQUITY
A42: Common stock | B42: 38 | C42: 38 | D42: 38
A43: Additional paid-in capital | B43: 6761 | C43: 6996 | D43: 7247
A44: Retained earnings | B44: 7093 | C44: 8090 | D44: 9297
A45: Accumulated other comprehensive loss | B45: -460 | C45: -458 | D45: -417
A46: Total shareholders' equity | B46: 13432 | C46: 14666 | D46: 16165
...

Sheet Checks
A4: Model checks.
B5: ='Three Statements'!B4 -> FY2023 | C5: ='Three Statements'!C4 -> FY2024 | D5: ='Three Statements'!D4 -> FY2025 | E5: ='Three Statements'!E4 -> FY2026F | F5: ='Three Statements'!F4 -> FY2027F | G5: ='Three Statements'!G4 -> FY2028F
A6: Balance sheet difference | B6: ='Three Statements'!B28-'Three Statements'!B47 -> 0 | C6: ='Three Statements'!C28-'Three Statements'!C47 -> 0 | D6: ='Three Statements'!D28-'Three Statements'!D47 -> 0 | E6: ='Three Statements'!E28-'Three Statements'!E47 -> 0 | F6: ='Three Statements'!F28-'Three Statements'!F47 -> 0 | G6: ='Three Statements'!G28-'Three Statements'!G47 -> 0
A7: Cash balance difference | B7: ='Three Statements'!B21-'Three Statements'!B78 -> 0 | C7: ='Three Statements'!C21-'Three Statements'!C78 -> 0 | D7: ='Three Statements'!D21-'Three Statements'!D78 -> 0 | E7: ='Three Statements'!E21-'Three Statements'!E78 -> 0 | F7: ='Three Statements'!F21-'Three Statements'!F78 -> 0 | G7: ='Three Statements'!G21-'Three Statements'!G78 -> 0
A8: Cash flow roll-forward difference | B8: ='Three Statements'!B77+'Three Statements'!B76-'Three Statements'!B78 -> 0 | C8: ='Three Statements'!C77+'Three Statements'!C76-'Three Statements'!C78 -> 0 | D8: ='Three Statements'!D77+'Three Statements'!D76-'Three Statements'!D78 -> 0 | E8: ='Three Statements'!E77+'Three Statements'!E76-'Three Statements'!E78 -> 0 | F8: ='Three Statements'!F77+'Three Statements'!F76-'Three Statements'!F78 -> 0 | G8: ='Three Statements'!G77+'Three Statements'!G76-'Three Statements'!G78 -> 0
